Workbook

Sheet Cover Page
B3: NETFLIX INDIA
B4: COMPREHENSIVE 3-STATEMENT FINANCIAL MODEL & DCF VALUATION
B5: All Projections Formula-Driven | Change Assumptions Sheet → Entire Model Updates
B7: DCF Enterprise Value | D7: Equity Value (DCF) | F7: WACC | H7: Terminal Growth Rate
B8: ='DCF & WACC'!B39 -> 15441.295 | D8: ='DCF & WACC'!B43 -> 16291.295 | F8: =Assumptions!B47 -> 0.1466 | H8: =Assumptions!B48 -> 0.045
B10: Analyst | D10: Akarsh Kumar Pandey
B12: Model Type | D12: 3-Statement Financial Model – Formula Driven
B13: Data Source | D13: Ministry of Corporate Affairs (MCA) – Netflix Entertainment Services India LLP
B14: WACC Formula | D14: Rf + Beta x MRP (CAPM) - All flows through DCF automatically
B15: Model Logic | D15: Change ANY yellow cell in Assumptions → entire IS / BS / CF / DCF updates
B17: SHEET INDEX & FORMULA ARCHITECTURE
B18: Cover Page | C18: This sheet – live KPI boxes linked to model outputs
B19: Assumptions | C19: ⭐ DRIVER SHEET – change yellow cells here to update entire model
B20: Income Statement | C20: Revenue, margins, NI – all formulas referencing Assumptions
B21: Balance Sheet | C21: Assets, liabilities, equity – RE rolls forward from IS Net Income
B22: Cash Flow | C22: OCF/ICF/FCF/Financing – all linked to IS + Assumptions
B23: DCF & WACC | C23: CAPM, discount factors, terminal value – all real Excel formulas
B24: Sensitivity Analysis | C24: Two-way table; base case cell live-linked to DCF EV
B25: Comparable Companies | C25: Peer comps; Netflix India multiples live from DCF sheet
B26: Scenario Analysis | C26: Bull/Base/Bear; Base EV live-linked to DCF

Sheet Assumptions
A1: ASSUMPTIONS & DRIVER SHEET – All Blue Cells Are Inputs | Yellow = Projection Assumptions | Green = Formula Outputs
A4: (₹ Crores) | B4: FY2021 | C4: FY2022 | D4: FY2023 | E4: FY2024 | F4: FY2025E | G4: FY2026P | H4: FY2027P | I4: FY2028P | J4: FY2029P | K4: FY2030P
A5: SECTION 1: REVENUE ASSUMPTIONS
A6: Total Revenue (₹ Crores) | B6: 950 | C6: 1837 | D6: 2286 | E6: 2846 | F6: 3769 | G6: =F6*(1+G7) -> 4296.66 | H6: =G6*(1+H7) -> 4915.379 | I6: =H6*(1+I7) -> 5613.3629 | J6: =I6*(1+J7) -> 6286.9664 | K6: =J6*(1+K7) -> 6915.663
A7: Revenue Growth Rate % | B7: - | C7: 0.934 | D7: 0.244 | E7: 0.245 | F7: 0.324 | G7: 0.14 | H7: 0.144 | I7: 0.142 | J7: 0.12 | K7: 0.1
A10: SECTION 2: PROFITABILITY MARGIN ASSUMPTIONS (change any cell → entire model updates)
A11: Gross Margin % | B11: 0.321 | C11: 0.33 | D11: 0.346 | E11: 0.368 | F11: 0.385 | G11: 0.345 | H11: 0.352 | I11: 0.358 | J11: 0.362 | K11: 0.365
A12: EBITDA Margin % | B12: 0.498 | C12: 0.281 | D12: 0.298 | E12: 0.32 | F12: 0.398 | G12: 0.41 | H12: 0.42 | I12: 0.425 | J12: 0.43 | K12: 0.43
A13: EBIT / Operating Margin % | B13: 0.016 | C13: 0.028 | D13: 0.038 | E13: 0.07 | F13: 0.098 | G13: 0.11 | H13: 0.125 | I13: 0.135 | J13: 0.145 | K13: 0.15
A14: Tax Rate % | B14: 0.333 | C14: 0.643 | D14: 0.628 | E14: 0.752 | F14: 0.778 | G14: 0.25 | H14: 0.25 | I14: 0.25 | J14: 0.25 | K14: 0.25
A17: SECTION 3: COST STRUCTURE (% of Revenue)
A18: Content Costs % Revenue | B18: 0.579 | C18: 0.574 | D18: 0.56 | E18: 0.541 | F18: 0.525 | G18: 0.513 | H18: 0.503 | I18: 0.493 | J18: 0.483 | K18: 0.473
A19: Technology % Revenue | B19: 0.1 | C19: 0.095 | D19: 0.094 | E19: 0.091 | F19: 0.09 | G19: 0.09 | H19: 0.09 | I19: 0.09 | J19: 0.09 | K19: 0.09
A20: Sales & Marketing % Revenue | B20: 0.2 | C20: 0.2 | D20: 0.2 | E20: 0.19 | F20: 0.18 | G20: 0.17 | H20: 0.165 | I20: 0.16 | J20: 0.155 | K20: 0.15
A21: G&A % Revenue | B21: 0.055 | C21: 0.053 | D21: 0.06 | E21: 0.06 | F21: 0.06 | G21: 0.058 | H21: 0.056 | I21: 0.054 | J21: 0.052 | K21: 0.05
A24: SECTION 4: OPERATIONAL KPIs
A25: Subscribers (Millions) | B25: 3.5 | C25: 5.5 | D25: 7 | E25: 17 | F25: 21 | G25: 25 | H25: 30 | I25: 35 | J25: 40 | K25: 44
A26: ARPU Monthly (₹) | B26: 2257 | C26: 2783 | D26: 2721 | E26: 1395 | F26: 1496 | G26: 1433 | H26: 1367 | I26: 1338 | J26: 1310 | K26: 1310
A27: Market Share % | B27: 0.085 | C27: 0.112 | D27: 0.145 | E27: 0.175 | F27: 0.19 | G27: 0.195 | H27: 0.2 | I27: 0.205 | J27: 0.21 | K27: 0.215
A30: SECTION 5: SCHEDULE INPUTS – D&A / CAPEX / CASH FLOW (₹ Crores – Absolute Values)
A31: D&A (₹ Cr) | B31: 25 | C31: 35 | D31: 45 | E31: 55 | F31: 70 | G31: 85 | H31: 100 | I31: 120 | J31: 140 | K31: 160
A32: Content Amortization (₹ Cr) | B32: 500 | C32: 800 | D32: 1000 | E32: 1200 | F32: 1400 | G32: 1600 | H32: 1800 | I32: 2000 | J32: 2200 | K32: 2400
A33: Stock-Based Comp (₹ Cr) | B33: 10 | C33: 15 | D33: 20 | E33: 25 | F33: 30 | G33: 35 | H33: 40 | I33: 45 | J33: 50 | K33: 55
A34: Content CapEx (₹ Cr) – outflow | B34: 500 | C34: 800 | D34: 1000 | E34: 1200 | F34: 1400 | G34: 1600 | H34: 1800 | I34: 2000 | J34: 2200 | K34: 2400
A35: PP&E CapEx (₹ Cr) – outflow | B35: 50 | C35: 60 | D35: 70 | E35: 80 | F35: 100 | G35: 120 | H35: 140 | I35: 160 | J35: 180 | K35: 200
A36: NWC Change (₹ Cr) | B36: -15 | C36: -28 | D36: -35 | E36: -45 | F36: -60 | G36: -65 | H36: -67 | I36: -65 | J36: -70 | K36: -75
A37: DCF Maintenance CapEx % of Revenue (for FCF calc) | B37: - | C37: - | D37: - | E37: - | F37: 0.3 | G37: 0.1 | H37: 0.095 | I37: 0.09 | J37: 0.085 | K37: 0.08 | L37: Used only in DCF FCF calc; separate from full content CapEx in CF statement
A38: Parent Capital Contributions (₹ Cr) | B38: 450 | C38: 280 | D38: 180 | E38: 120 | F38: 80 | G38: 40 | H38: 30 | I38: 20 | J38: 10 | K38: 0
A39: Share Buybacks (₹ Cr) – outflow | B39: -30 | C39: -55 | D39: -68 | E39: -82 | F39: -110 | G39: -120 | H39: -125 | I39: -130 | J39: -140 | K39: -150
A42: SECTION 6: DCF VALUATION PARAMETERS (single values – used by DCF sheet)
A43: Risk-Free Rate (India 10Y G-Sec) | B43: 0.0661 | C43: India 10Y G-Sec Dec 2025
A44: Beta | B44: 1.15 | C44: Netflix global unlevered; levered = unlevered (zero debt)
A45: Market Risk Premium (MRP) | B45: 0.07 | C45: Incwert India ERP Study 2025 (7th Ed.)
A46: Cost of Equity (Ke) = Rf + β × MRP | B46: =ROUND(B43+B44*B45,4) -> 0.1466 | C46: ▶ FORMULA: =Risk-Free Rate + Beta × Market Risk Premium (CAPM)
A47: WACC (=Ke since zero debt) | B47: =B49*B46 -> 0.1466 | C47: ▶ FORMULA: =Equity Weight × Ke (Debt Weight × Kd = 0)
A48: Terminal Growth Rate (g) | B48: 0.045 | C48: India long-term nominal GDP proxy
A49: Equity Weight (E/V) | B49: 1 | C49: 100% equity financed – no debt
A50: Debt Weight (D/V) | B50: 0 | C50: Zero debt throughout model period
A51: ⚠ YELLOW cells = projection assumptions (change these to run scenarios)
A52: ⚠ GREY cells = historical actuals (do not change)

Sheet Income Statement
A1: INCOME STATEMENT – NETFLIX INDIA (₹ Crores) | Green = Link | Black = Formula
A4: (₹ Crores) | B4: FY2021 | C4: FY2022 | D4: FY2023 | E4: FY2024 | F4: FY2025E | G4: FY2026P | H4: FY2027P | I4: FY2028P | J4: FY2029P | K4: FY2030P
A5: REVENUE
A6: Total Revenue | B6: =Assumptions!B6 -> 950 | C6: =Assumptions!C6 -> 1837 | D6: =Assumptions!D6 -> 2286 | E6: =Assumptions!E6 -> 2846 | F6: =Assumptions!F6 -> 3769 | G6: =Assumptions!G6 -> 4296.66 | H6: =Assumptions!H6 -> 4915.379 | I6: =Assumptions!I6 -> 5613.3629 | ... K6: =Assumptions!K6 -> 6915.663
A7: YoY Revenue Growth % | B7: - | C7: =C6/B6-1 -> 0.93368421 | D7: =D6/C6-1 -> 0.24442025 | E7: =E6/D6-1 -> 0.24496938 | F7: =F6/E6-1 -> 0.32431483 | G7: =G6/F6-1 -> 0.14 | H7: =H6/G6-1 -> 0.144 | I7: =I6/H6-1 -> 0.142 | J7: =J6/I6-1 -> 0.12 | K7: =K6/J6-1 -> 0.1
A8: COST OF REVENUE
A9: Content Costs / Amortization | B9: =-B6*Assumptions!B18 -> -550.05 | C9: =-C6*Assumptions!C18 -> -1054.438 | D9: =-D6*Assumptions!D18 -> -1280.16 | E9: =-E6*Assumptions!E18 -> -1539.686 | F9: =-F6*Assumptions!F18 -> -1978.725 | G9: =-G6*Assumptions!G18 -> -2204.1866 | H9: =-H6*Assumptions!H18 -> -2472.4357 | I9: =-I6*Assumptions!I18 -> -2767.3879 | ... K9: =-K6*Assumptions!K18 -> -3271.1086
A10: Technology & Infrastructure | B10: =-B6*Assumptions!B19 -> -95 | C10: =-C6*Assumptions!C19 -> -174.515 | D10: =-D6*Assumptions!D19 -> -214.884 | E10: =-E6*Assumptions!E19 -> -258.986 | F10: =-F6*Assumptions!F19 -> -339.21 | G10: =-G6*Assumptions!G19 -> -386.6994 | H10: =-H6*Assumptions!H19 -> -442.38411 | I10: =-I6*Assumptions!I19 -> -505.20266 | ... K10: =-K6*Assumptions!K19 -> -622.40967
A11: Total Cost of Revenue | B11: =B9+B10 -> -645.05 | C11: =C9+C10 -> -1228.953 | D11: =D9+D10 -> -1495.044 | E11: =E9+E10 -> -1798.672 | F11: =F9+F10 -> -2317.935 | G11: =G9+G10 -> -2590.886 | H11: =H9+H10 -> -2914.8198 | I11: =I9+I10 -> -3272.5905 | ... K11: =K9+K10 -> -3893.5183
A12: GROSS PROFIT | B12: =B6+B11 -> 304.95 | C12: =C6+C11 -> 608.047 | D12: =D6+D11 -> 790.956 | E12: =E6+E11 -> 1047.328 | F12: =F6+F11 -> 1451.065 | G12: =G6+G11 -> 1705.774 | H12: =H6+H11 -> 2000.5593 | I12: =I6+I11 -> 2340.7723 | ... K12: =K6+K11 -> 3022.1448
A13: Gross Margin % | B13: =B12/B6 -> 0.321 | C13: =C12/C6 -> 0.331 | D13: =D12/D6 -> 0.346 | E13: =E12/E6 -> 0.368 | F13: =F12/F6 -> 0.385 | G13: =G12/G6 -> 0.397 | H13: =H12/H6 -> 0.407 | I13: =I12/I6 -> 0.417 | ... K13: =K12/K6 -> 0.437
A14: OPERATING EXPENSES
A15: Sales & Marketing | B15: =-B6*Assumptions!B20 -> -190 | C15: =-C6*Assumptions!C20 -> -367.4 | D15: =-D6*Assumptions!D20 -> -457.2 | E15: =-E6*Assumptions!E20 -> -540.74 | F15: =-F6*Assumptions!F20 -> -678.42 | G15: =-G6*Assumptions!G20 -> -730.4322 | H15: =-H6*Assumptions!H20 -> -811.03754 | I15: =-I6*Assumptions!I20 -> -898.13806 | ... K15: =-K6*Assumptions!K20 -> -1037.3495
A16: Technology & Development | B16: =-B6*Assumptions!B19 -> -95 | C16: =-C6*Assumptions!C19 -> -174.515 | D16: =-D6*Assumptions!D19 -> -214.884 | E16: =-E6*Assumptions!E19 -> -258.986 | F16: =-F6*Assumptions!F19 -> -339.21 | G16: =-G6*Assumptions!G19 -> -386.6994 | H16: =-H6*Assumptions!H19 -> -442.38411 | I16: =-I6*Assumptions!I19 -> -505.20266 | ... K16: =-K6*Assumptions!K19 -> -622.40967
A17: General & Administrative | B17: =-B6*Assumptions!B21 -> -52.25 | C17: =-C6*Assumptions!C21 -> -97.361 | D17: =-D6*Assumptions!D21 -> -137.16 | E17: =-E6*Assumptions!E21 -> -170.76 | F17: =-F6*Assumptions!F21 -> -226.14 | G17: =-G6*Assumptions!G21 -> -249.20628 | H17: =-H6*Assumptions!H21 -> -275.26123 | I17: =-I6*Assumptions!I21 -> -303.12159 | ... K17: =-K6*Assumptions!K21 -> -345.78315
A18: Total Operating Expenses | B18: =B15+B16+B17 -> -337.25 | C18: =C15+C16+C17 -> -639.276 | D18: =D15+D16+D17 -> -809.244 | E18: =E15+E16+E17 -> -970.486 | F18: =F15+F16+F17 -> -1243.77 | G18: =G15+G16+G17 -> -1366.3379 | H18: =H15+H16+H17 -> -1528.6829 | I18: =I15+I16+I17 -> -1706.4623 | ... K18: =K15+K16+K17 -> -2005.5423
A19: PROFITABILITY
A20: EBITDA | B20: =B6*Assumptions!B12 -> 473.1 | C20: =C6*Assumptions!C12 -> 516.197 | D20: =D6*Assumptions!D12 -> 681.228 | E20: =E6*Assumptions!E12 -> 910.72 | F20: =F6*Assumptions!F12 -> 1500.062 | G20: =G6*Assumptions!G12 -> 1761.6306 | H20: =H6*Assumptions!H12 -> 2064.4592 | I20: =I6*Assumptions!I12 -> 2385.6792 | ... K20: =K6*Assumptions!K12 -> 2973.7351
A21: EBITDA Margin % | B21: =B20/B6 -> 0.498 | C21: =C20/C6 -> 0.281 | D21: =D20/D6 -> 0.298 | E21: =E20/E6 -> 0.32 | F21: =F20/F6 -> 0.398 | G21: =G20/G6 -> 0.41 | H21: =H20/H6 -> 0.42 | I21: =I20/I6 -> 0.425 | ... K21: =K20/K6 -> 0.43
A22: Depreciation & Amortization | B22: =-(B20-B23) -> -457.9 | C22: =-(C20-C23) -> -464.761 | D22: =-(D20-D23) -> -594.36 | E22: =-(E20-E23) -> -711.5 | F22: =-(F20-F23) -> -1130.7 | G22: =-(G20-G23) -> -1288.998 | H22: =-(H20-H23) -> -1450.0368 | I22: =-(I20-I23) -> -1627.8752 | ... K22: =-(K20-K23) -> -1936.3857
A23: EBIT / Operating Income | B23: =B6*Assumptions!B13 -> 15.2 | C23: =C6*Assumptions!C13 -> 51.436 | D23: =D6*Assumptions!D13 -> 86.868 | E23: =E6*Assumptions!E13 -> 199.22 | F23: =F6*Assumptions!F13 -> 369.362 | G23: =G6*Assumptions!G13 -> 472.6326 | H23: =H6*Assumptions!H13 -> 614.42238 | I23: =I6*Assumptions!I13 -> 757.80399 | ... K23: =K6*Assumptions!K13 -> 1037.3495
A24: Operating Margin % | B24: =B23/B6 -> 0.016 | C24: =C23/C6 -> 0.028 | D24: =D23/D6 -> 0.038 | E24: =E23/E6 -> 0.07 | F24: =F23/F6 -> 0.098 | G24: =G23/G6 -> 0.11 | H24: =H23/H6 -> 0.125 | I24: =I23/I6 -> 0.135 | ... K24: =K23/K6 -> 0.15
A25: Pre-Tax Income | B25: =B23 -> 15.2 | C25: =C23 -> 51.436 | D25: =D23 -> 86.868 | E25: =E23 -> 199.22 | F25: =F23 -> 369.362 | G25: =G23 -> 472.6326 | H25: =H23 -> 614.42238 | I25: =I23 -> 757.80399 | ... K25: =K23 -> 1037.3495
A26: Income Tax | B26: =IF(B25>0,-B25*Assumptions!B14,0) -> -5.0616 | C26: =IF(C25>0,-C25*Assumptions!C14,0) -> -33.073348 | D26: =IF(D25>0,-D25*Assumptions!D14,0) -> -54.553104 | E26: =IF(E25>0,-E25*Assumptions!E14,0) -> -149.81344 | F26: =IF(F25>0,-F25*Assumptions!F14,0) -> -287.36364 | G26: =IF(G25>0,-G25*Assumptions!G14,0) -> -118.15815 | H26: =IF(H25>0,-H25*Assumptions!H14,0) -> -153.6056 | I26: =IF(I25>0,-I25*Assumptions!I14,0) -> -189.451 | ... K26: =IF(K25>0,-K25*Assumptions!K14,0) -> -259.33736
A27: Effective Tax Rate % | B27: =IF(B25<>0,ABS(B26/B25),0) -> 0.333 | C27: =IF(C25<>0,ABS(C26/C25),0) -> 0.643 | D27: =IF(D25<>0,ABS(D26/D25),0) -> 0.628 | E27: =IF(E25<>0,ABS(E26/E25),0) -> 0.752 | F27: =IF(F25<>0,ABS(F26/F25),0) -> 0.778 | G27: =IF(G25<>0,ABS(G26/G25),0) -> 0.25 | H27: =IF(H25<>0,ABS(H26/H25),0) -> 0.25 | I27: =IF(I25<>0,ABS(I26/I25),0) -> 0.25 | ... K27: =IF(K25<>0,ABS(K26/K25),0) -> 0.25
A28: NET INCOME (PAT) | B28: =B25+B26 -> 10.1384 | C28: =C25+C26 -> 18.362652 | D28: =D25+D26 -> 32.314896 | E28: =E25+E26 -> 49.40656 | F28: =F25+F26 -> 81.998364 | G28: =G25+G26 -> 354.47445 | H28: =H25+H26 -> 460.81679 | I28: =I25+I26 -> 568.35299 | ... K28: =K25+K26 -> 778.01209
A29: Net Margin % | B29: =B28/B6 -> 0.010672 | C29: =C28/C6 -> 0.009996 | D29: =D28/D6 -> 0.014136 | E29: =E28/E6 -> 0.01736 | F29: =F28/F6 -> 0.021756 | G29: =G28/G6 -> 0.0825 | H29: =H28/H6 -> 0.09375 | I29: =I28/I6 -> 0.10125 | ... K29: =K28/K6 -> 0.1125
A30: OPERATIONAL KPIs (linked from Assumptions)
A31: Subscribers (Millions) | B31: =Assumptions!B25 -> 3.5 | C31: =Assumptions!C25 -> 5.5 | D31: =Assumptions!D25 -> 7 | E31: =Assumptions!E25 -> 17 | F31: =Assumptions!F25 -> 21 | G31: =Assumptions!G25 -> 25 | H31: =Assumptions!H25 -> 30 | I31: =Assumptions!I25 -> 35 | ... K31: =Assumptions!K25 -> 44
A32: ARPU Monthly (₹) | B32: =Assumptions!B26 -> 2257 | C32: =Assumptions!C26 -> 2783 | D32: =Assumptions!D26 -> 2721 | E32: =Assumptions!E26 -> 1395 | F32: =Assumptions!F26 -> 1496 | G32: =Assumptions!G26 -> 1433 | H32: =Assumptions!H26 -> 1367 | I32: =Assumptions!I26 -> 1338 | ... K32: =Assumptions!K26 -> 1310
A33: Market Share % | B33: =Assumptions!B27 -> 0.085 | C33: =Assumptions!C27 -> 0.112 | D33: =Assumptions!D27 -> 0.145 | E33: =Assumptions!E27 -> 0.175 | F33: =Assumptions!F27 -> 0.19 | G33: =Assumptions!G27 -> 0.195 | H33: =Assumptions!H27 -> 0.2 | I33: =Assumptions!I27 -> 0.205 | ... K33: =Assumptions!K27 -> 0.215
A35: FORMULA LEGEND
A36: Blue cells | B36: Hardcoded inputs in Assumptions sheet
A37: Green cells | B37: Direct cross-sheet link (=Assumptions!...)
A38: Black cells | B38: Formula calculated from other cells (see formula bar when clicking any black cell)

Sheet Balance Sheet
A1: BALANCE SHEET – NETFLIX INDIA (₹ Crores)
A4: (₹ Crores) | B4: FY2021 | C4: FY2022 | D4: FY2023 | E4: FY2024 | F4: FY2025E | G4: FY2026P | H4: FY2027P | I4: FY2028P | J4: FY2029P | K4: FY2030P
A5: ASSETS
A6: Cash & Cash Equivalents | B6: 362 | C6: 571 | D6: 676 | E6: 800 | F6: 800 | G6: ='Cash Flow'!G29 -> 1107.6953 | H6: ='Cash Flow'!H29 -> 1378.5121 | I6: ='Cash Flow'!I29 -> 1744.8651 | J6: ='Cash Flow'!J29 -> 2202.5727 | K6: ='Cash Flow'!K29 -> 2730.5848
A7: Marketable Securities | B7: 20 | C7: 30 | D7: 40 | E7: 50 | F7: 50 | G7: =F7*1.02 -> 51 | H7: =G7*1.02 -> 52.02 | I7: =H7*1.02 -> 53.0604 | J7: =I7*1.02 -> 54.121608 | K7: =J7*1.02 -> 55.20404
A8: Trade Receivables | B8: 86 | C8: 137 | D8: 207 | E8: 86 | F8: 137 | G8: ='Income Statement'!G6*15/365 -> 176.57507 | H8: ='Income Statement'!H6*15/365 -> 202.00188 | I8: ='Income Statement'!I6*15/365 -> 230.68615 | J8: ='Income Statement'!J6*15/365 -> 258.36848 | K8: ='Income Statement'!K6*15/365 -> 284.20533
A9: Prepaid Expenses & Other | B9: 15 | C9: 20 | D9: 28 | E9: 40 | F9: 40 | G9: =F9*1.05 -> 42 | H9: =G9*1.05 -> 44.1 | I9: =H9*1.05 -> 46.305 | J9: =I9*1.05 -> 48.62025 | K9: =J9*1.05 -> 51.051263
A10: TOTAL CURRENT ASSETS | B10: =SUM(B6:B9) -> 483 | C10: =SUM(C6:C9) -> 758 | D10: =SUM(D6:D9) -> 951 | E10: =SUM(E6:E9) -> 976 | F10: =SUM(F6:F9) -> 1027 | G10: =SUM(G6:G9) -> 1377.2704 | H10: =SUM(H6:H9) -> 1676.634 | I10: =SUM(I6:I9) -> 2074.9166 | ... K10: =SUM(K6:K9) -> 3121.0454
A12: Content Library (Net) | B12: 535 | C12: 285 | D12: 200 | E12: 850 | F12: 850 | G12: =MAX(F12-Assumptions!G31,0) -> 765 | H12: =MAX(G12-Assumptions!H31,0) -> 665 | I12: =MAX(H12-Assumptions!I31,0) -> 545 | J12: =MAX(I12-Assumptions!J31,0) -> 405 | K12: =MAX(J12-Assumptions!K31,0) -> 245
A13: Property & Equipment (Net) | B13: 130 | C13: 155 | D13: 185 | E13: 220 | F13: 265 | G13: =F13+Assumptions!G35-Assumptions!G31/2 -> 342.5 | H13: =G13+Assumptions!H35-Assumptions!H31/2 -> 432.5 | I13: =H13+Assumptions!I35-Assumptions!I31/2 -> 532.5 | J13: =I13+Assumptions!J35-Assumptions!J31/2 -> 642.5 | K13: =J13+Assumptions!K35-Assumptions!K31/2 -> 762.5
A14: Intangibles & Goodwill | B14: 200 | C14: 230 | D14: 260 | E14: 280 | F14: 300 | G14: =F14 -> 300 | H14: =G14 -> 300 | I14: =H14 -> 300 | J14: =I14 -> 300 | K14: =J14 -> 300
A15: Other Non-Current Assets | B15: 50 | C15: 60 | D15: 65 | E15: 71 | F15: 75 | G15: =F15*1.03 -> 77.25 | H15: =G15*1.03 -> 79.5675 | I15: =H15*1.03 -> 81.954525 | J15: =I15*1.03 -> 84.413161 | K15: =J15*1.03 -> 86.945556
A16: TOTAL NON-CURRENT ASSETS | B16: =SUM(B12:B15) -> 915 | C16: =SUM(C12:C15) -> 730 | D16: =SUM(D12:D15) -> 710 | E16: =SUM(E12:E15) -> 1421 | F16: =SUM(F12:F15) -> 1490 | G16: =SUM(G12:G15) -> 1484.75 | H16: =SUM(H12:H15) -> 1477.0675 | I16: =SUM(I12:I15) -> 1459.4545 | ... K16: =SUM(K12:K15) -> 1394.4456
A17: TOTAL ASSETS | B17: =B10+B16 -> 1398 | C17: =C10+C16 -> 1488 | D17: =D10+D16 -> 1661 | E17: =E10+E16 -> 2397 | F17: =F10+F16 -> 2517 | G17: =G10+G16 -> 2862.0204 | H17: =H10+H16 -> 3153.7015 | I17: =I10+I16 -> 3534.3712 | ... K17: =K10+K16 -> 4515.491
A18: LIABILITIES & EQUITY
A20: Trade Payables | B20: 90 | C20: 130 | D20: 170 | E20: 703 | F20: 863 | G20: =ABS('Income Statement'!G11)*30/365 -> 212.94953 | H20: =ABS('Income Statement'!H11)*30/365 -> 239.57423 | I20: =ABS('Income Statement'!I11)*30/365 -> 268.98005 | J20: =ABS('Income Statement'!J11)*30/365 -> 296.09028 | K20: =ABS('Income Statement'!K11)*30/365 -> 320.0152
A21: Accrued Expenses | B21: 80 | C21: 110 | D21: 140 | E21: 250 | F21: 250 | G21: =F21*1.05 -> 262.5 | H21: =G21*1.05 -> 275.625 | I21: =H21*1.05 -> 289.40625 | J21: =I21*1.05 -> 303.87656 | K21: =J21*1.05 -> 319.07039
A22: Deferred Revenue | B22: 50 | C22: 80 | D22: 100 | E22: 150 | F22: 160 | G22: =F22*1.05 -> 168 | H22: =G22*1.05 -> 176.4 | I22: =H22*1.05 -> 185.22 | J22: =I22*1.05 -> 194.481 | K22: =J22*1.05 -> 204.20505
A23: Current Content Liabilities | B23: 150 | C23: 220 | D23: 280 | E23: 450 | F23: 600 | G23: =F23*1.05 -> 630 | H23: =G23*1.05 -> 661.5 | I23: =H23*1.05 -> 694.575 | J23: =I23*1.05 -> 729.30375 | K23: =J23*1.05 -> 765.76894
A24: TOTAL CURRENT LIABILITIES | B24: =SUM(B20:B23) -> 370 | C24: =SUM(C20:C23) -> 540 | D24: =SUM(D20:D23) -> 690 | E24: =SUM(E20:E23) -> 1553 | F24: =SUM(F20:F23) -> 1873 | G24: =SUM(G20:G23) -> 1273.4495 | H24: =SUM(H20:H23) -> 1353.0992 | I24: =SUM(I20:I23) -> 1438.1813 | ... K24: =SUM(K20:K23) -> 1609.0596
A26: Long-Term Debt (Zero) | B26: 0 | C26: 0 | D26: 0 | E26: 0 | F26: 0 | G26: =0 -> 0 | H26: =0 -> 0 | I26: =0 -> 0 | J26: =0 -> 0 | K26: =0 -> 0
A27: Content Liabilities (LT) | B27: 100 | C27: 150 | D27: 180 | E27: 200 | F27: 200 | G27: =F27*0.98 -> 196 | H27: =G27*0.98 -> 192.08 | I27: =H27*0.98 -> 188.2384 | J27: =I27*0.98 -> 184.47363 | K27: =J27*0.98 -> 180.78416
A28: Deferred Tax Liabilities | B28: 20 | C28: 30 | D28: 40 | E28: 50 | F28: 50 | G28: =F28*1.05 -> 52.5 | H28: =G28*1.05 -> 55.125 | I28: =H28*1.05 -> 57.88125 | J28: =I28*1.05 -> 60.775313 | K28: =J28*1.05 -> 63.814078
A29: TOTAL NON-CURRENT LIAB. | B29: =SUM(B26:B28) -> 120 | C29: =SUM(C26:C28) -> 180 | D29: =SUM(D26:D28) -> 220 | E29: =SUM(E26:E28) -> 250 | F29: =SUM(F26:F28) -> 250 | G29: =SUM(G26:G28) -> 248.5 | H29: =SUM(H26:H28) -> 247.205 | I29: =SUM(I26:I28) -> 246.11965 | ... K29: =SUM(K26:K28) -> 244.59824
A31: Common Stock / Paid-in Capital | B31: 600 | C31: 600 | D31: 600 | E31: 65 | F31: 65 | G31: =F31 -> 65 | H31: =G31 -> 65 | I31: =H31 -> 65 | J31: =I31 -> 65 | K31: =J31 -> 65
A32: Retained Earnings | B32: 12 | C32: 32 | D32: 67 | E32: 119 | F32: 218 | G32: =F32+'Income Statement'!G28 -> 572.47445 | H32: =G32+'Income Statement'!H28 -> 1033.2912 | I32: =H32+'Income Statement'!I28 -> 1601.6442 | J32: =I32+'Income Statement'!J28 -> 2285.3518 | K32: =J32+'Income Statement'!K28 -> 3063.3639
A33: Treasury Stock (Buybacks) | B33: -30 | C33: -85 | D33: -153 | E33: -165 | F33: -165 | G33: =F33+Assumptions!G38 -> -125 | H33: =G33+Assumptions!H38 -> -95 | I33: =H33+Assumptions!I38 -> -75 | J33: =I33+Assumptions!J38 -> -65 | K33: =J33+Assumptions!K38 -> -65
A34: Other Equity | B34: =B17-B24-B29-B31-B32-B33 -> 326 | C34: =C17-C24-C29-C31-C32-C33 -> 221 | D34: =D17-D24-D29-D31-D32-D33 -> 237 | E34: =E17-E24-E29-E31-E32-E33 -> 575 | F34: =F17-F24-F29-F31-F32-F33 -> 276 | G34: =G17-G24-G29-G31-G32-G33 -> 827.59641 | H34: =H17-H24-H29-H31-H32-H33 -> 550.10602 | I34: =I17-I24-I29-I31-I32-I33 -> 258.426 | ... K34: =K17-K24-K29-K31-K32-K33 -> -401.53076
A35: TOTAL SHAREHOLDERS' EQUITY | B35: =SUM(B31:B34) -> 908 | C35: =SUM(C31:C34) -> 768 | D35: =SUM(D31:D34) -> 751 | E35: =SUM(E31:E34) -> 594 | F35: =SUM(F31:F34) -> 394 | G35: =SUM(G31:G34) -> 1340.0709 | H35: =SUM(H31:H34) -> 1553.3973 | I35: =SUM(I31:I34) -> 1850.0702 | ... K35: =SUM(K31:K34) -> 2661.8332
A36: TOTAL LIAB. & EQUITY (Check = 0 if balanced) | B36: =B17-B24-B29-B35 -> 0 | C36: =C17-C24-C29-C35 -> 0 | D36: =D17-D24-D29-D35 -> 0 | E36: =E17-E24-E29-E35 -> 0 | F36: =F17-F24-F29-F35 -> 0 | G36: =G17-G24-G29-G35 -> 0 | H36: =H17-H24-H29-H35 -> 0 | I36: =I17-I24-I29-I35 -> 0 | ... K36: =K17-K24-K29-K35 -> 0

Sheet Cash Flow
A1: CASH FLOW STATEMENT – NETFLIX INDIA (₹ Crores)
A4: (₹ Crores) | B4: FY2021 | C4: FY2022 | D4: FY2023 | E4: FY2024 | F4: FY2025E | G4: FY2026P | H4: FY2027P | I4: FY2028P | J4: FY2029P | K4: FY2030P
A5: OPERATING ACTIVITIES
A6: Net Income (PAT) | B6: ='Income Statement'!B28 -> 10.1384 | C6: ='Income Statement'!C28 -> 18.362652 | D6: ='Income Statement'!D28 -> 32.314896 | E6: ='Income Statement'!E28 -> 49.40656 | F6: ='Income Statement'!F28 -> 81.998364 | G6: ='Income Statement'!G28 -> 354.47445 | H6: ='Income Statement'!H28 -> 460.81679 | I6: ='Income Statement'!I28 -> 568.35299 | ... K6: ='Income Statement'!K28 -> 778.01209
A7: Add: Depreciation & Amortization | B7: =Assumptions!B31 -> 25 | C7: =Assumptions!C31 -> 35 | D7: =Assumptions!D31 -> 45 | E7: =Assumptions!E31 -> 55 | F7: =Assumptions!F31 -> 70 | G7: =Assumptions!G31 -> 85 | H7: =Assumptions!H31 -> 100 | I7: =Assumptions!I31 -> 120 | ... K7: =Assumptions!K31 -> 160
A8: Add: Content Amortization | B8: =Assumptions!B32 -> 500 | C8: =Assumptions!C32 -> 800 | D8: =Assumptions!D32 -> 1000 | E8: =Assumptions!E32 -> 1200 | F8: =Assumptions!F32 -> 1400 | G8: =Assumptions!G32 -> 1600 | H8: =Assumptions!H32 -> 1800 | I8: =Assumptions!I32 -> 2000 | ... K8: =Assumptions!K32 -> 2400
A9: Add: Stock-Based Compensation | B9: =Assumptions!B33 -> 10 | C9: =Assumptions!C33 -> 15 | D9: =Assumptions!D33 -> 20 | E9: =Assumptions!E33 -> 25 | F9: =Assumptions!F33 -> 30 | G9: =Assumptions!G33 -> 35 | H9: =Assumptions!H33 -> 40 | I9: =Assumptions!I33 -> 45 | ... K9: =Assumptions!K33 -> 55
A10: Changes in Working Capital | B10: =Assumptions!B36 -> -15 | C10: =Assumptions!C36 -> -28 | D10: =Assumptions!D36 -> -35 | E10: =Assumptions!E36 -> -45 | F10: =Assumptions!F36 -> -60 | G10: =Assumptions!G36 -> -65 | H10: =Assumptions!H36 -> -67 | I10: =Assumptions!I36 -> -65 | ... K10: =Assumptions!K36 -> -75
A11: NET OPERATING CASH FLOW | B11: =SUM(B6:B10) -> 530.1384 | C11: =SUM(C6:C10) -> 840.36265 | D11: =SUM(D6:D10) -> 1062.3149 | E11: =SUM(E6:E10) -> 1284.4066 | F11: =SUM(F6:F10) -> 1521.9984 | G11: =SUM(G6:G10) -> 2009.4745 | H11: =SUM(H6:H10) -> 2333.8168 | I11: =SUM(I6:I10) -> 2668.353 | ... K11: =SUM(K6:K10) -> 3318.0121
A12: INVESTING ACTIVITIES
A13: Content CapEx (outflow) | B13: =-Assumptions!B34 -> -500 | C13: =-Assumptions!C34 -> -800 | D13: =-Assumptions!D34 -> -1000 | E13: =-Assumptions!E34 -> -1200 | F13: =-Assumptions!F34 -> -1400 | G13: =-Assumptions!G34 -> -1600 | H13: =-Assumptions!H34 -> -1800 | I13: =-Assumptions!I34 -> -2000 | ... K13: =-Assumptions!K34 -> -2400
A14: PP&E / Technology CapEx (outflow) | B14: =-Assumptions!B35 -> -50 | C14: =-Assumptions!C35 -> -60 | D14: =-Assumptions!D35 -> -70 | E14: =-Assumptions!E35 -> -80 | F14: =-Assumptions!F35 -> -100 | G14: =-Assumptions!G35 -> -120 | H14: =-Assumptions!H35 -> -140 | I14: =-Assumptions!I35 -> -160 | ... K14: =-Assumptions!K35 -> -200
A15: Other Investing Activities | B15: =-Assumptions!B35/5 -> -10 | C15: =-Assumptions!C35/5 -> -12 | D15: =-Assumptions!D35/5 -> -14 | E15: =-Assumptions!E35/5 -> -16 | F15: =-Assumptions!F35/5 -> -20 | G15: =-Assumptions!G35/5 -> -24 | H15: =-Assumptions!H35/5 -> -28 | I15: =-Assumptions!I35/5 -> -32 | ... K15: =-Assumptions!K35/5 -> -40
A16: NET INVESTING CASH FLOW | B16: =SUM(B13:B15) -> -560 | C16: =SUM(C13:C15) -> -872 | D16: =SUM(D13:D15) -> -1084 | E16: =SUM(E13:E15) -> -1296 | F16: =SUM(F13:F15) -> -1520 | G16: =SUM(G13:G15) -> -1744 | H16: =SUM(H13:H15) -> -1968 | I16: =SUM(I13:I15) -> -2192 | ... K16: =SUM(K13:K15) -> -2640
A17: FREE CASH FLOW
A18: FREE CASH FLOW (OCF + Total CapEx) | B18: =B11+B13+B14 -> -19.8616 | C18: =C11+C13+C14 -> -19.637348 | D18: =D11+D13+D14 -> -7.685104 | E18: =E11+E13+E14 -> 4.40656 | F18: =F11+F13+F14 -> 21.998364 | G18: =G11+G13+G14 -> 289.47445 | H18: =H11+H13+H14 -> 393.81678 | I18: =I11+I13+I14 -> 508.35299 | ... K18: =K11+K13+K14 -> 718.01209
A19: FCF Margin % | B19: =B18/'Income Statement'!B6 -> -0.020906947 | C19: =C18/'Income Statement'!C6 -> -0.010689901 | D19: =D18/'Income Statement'!D6 -> -0.0033618128 | E19: =E18/'Income Statement'!E6 -> 0.0015483345 | F19: =F18/'Income Statement'!F6 -> 0.005836658 | G19: =G18/'Income Statement'!G6 -> 0.06737197 | H19: =H18/'Income Statement'!H6 -> 0.080119312 | I19: =I18/'Income Statement'!I6 -> 0.09056122 | ... K19: =K18/'Income Statement'!K6 -> 0.10382404
A20: FINANCING ACTIVITIES
A21: Debt Issuance / (Repayment) | B21: =0 -> 0 | C21: =0 -> 0 | D21: =0 -> 0 | E21: =0 -> 0 | F21: =0 -> 0 | G21: =0 -> 0 | H21: =0 -> 0 | I21: =0 -> 0 | ... K21: =0 -> 0
A22: Share Buybacks | B22: =Assumptions!B39 -> -30 | C22: =Assumptions!C39 -> -55 | D22: =Assumptions!D39 -> -68 | E22: =Assumptions!E39 -> -82 | F22: =Assumptions!F39 -> -110 | G22: =Assumptions!G39 -> -120 | H22: =Assumptions!H39 -> -125 | I22: =Assumptions!I39 -> -130 | ... K22: =Assumptions!K39 -> -150
A23: Dividend Payments | B23: =0 -> 0 | C23: =0 -> 0 | D23: =0 -> 0 | E23: =0 -> 0 | F23: =0 -> 0 | G23: =0 -> 0 | H23: =0 -> 0 | I23: =0 -> 0 | ... K23: =0 -> 0
A24: Parent Capital Contributions | B24: =Assumptions!B38 -> 450 | C24: =Assumptions!C38 -> 280 | D24: =Assumptions!D38 -> 180 | E24: =Assumptions!E38 -> 120 | F24: =Assumptions!F38 -> 80 | G24: =Assumptions!G38 -> 40 | H24: =Assumptions!H38 -> 30 | I24: =Assumptions!I38 -> 20 | ... K24: =Assumptions!K38 -> 0
A25: NET FINANCING CASH FLOW | B25: =SUM(B21:B24) -> 420 | C25: =SUM(C21:C24) -> 225 | D25: =SUM(D21:D24) -> 112 | E25: =SUM(E21:E24) -> 38 | F25: =SUM(F21:F24) -> -30 | G25: =SUM(G21:G24) -> -80 | H25: =SUM(H21:H24) -> -95 | I25: =SUM(I21:I24) -> -110 | ... K25: =SUM(K21:K24) -> -150
A26: CASH POSITION RECONCILIATION
A27: Beginning Cash Balance | B27: 250 | C27: =B29 -> 640.1384 | D27: =C29 -> 833.50105 | E27: =D29 -> 923.81595 | F27: =E29 -> 950.22251 | G27: =F29 -> 922.22087 | H27: =G29 -> 1107.6953 | I27: =H29 -> 1378.5121 | J27: =I29 -> 1744.8651 | K27: =J29 -> 2202.5727
A28: Net Change in Cash | B28: =B11+B16+B25 -> 390.1384 | C28: =C11+C16+C25 -> 193.36265 | D28: =D11+D16+D25 -> 90.314896 | E28: =E11+E16+E25 -> 26.40656 | F28: =F11+F16+F25 -> -28.001636 | G28: =G11+G16+G25 -> 185.47445 | H28: =H11+H16+H25 -> 270.81678 | I28: =I11+I16+I25 -> 366.35299 | ... K28: =K11+K16+K25 -> 528.01209
A29: ENDING CASH BALANCE | B29: =B27+B28 -> 640.1384 | C29: =C27+C28 -> 833.50105 | D29: =D27+D28 -> 923.81595 | E29: =E27+E28 -> 950.22251 | F29: =F27+F28 -> 922.22087 | G29: =G27+G28 -> 1107.6953 | H29: =H27+H28 -> 1378.5121 | I29: =I27+I28 -> 1744.8651 | ... K29: =K27+K28 -> 2730.5848

Sheet DCF & WACC
A1: DCF VALUATION & WACC – NETFLIX INDIA | All cells formula-driven from Assumptions
A3: WACC CALCULATION (all values link from Assumptions – change Assumptions!B42:B49 to update)
A6: Risk-Free Rate (Rf) – India 10Y G-Sec | B6: =Assumptions!B43 -> 0.0661 | C6: Source: India 10Y G-Sec (Dec 2025)
A7: Beta (Technology / Streaming Sector avg.) | B7: =Assumptions!B44 -> 1.15 | C7: Netflix global; unlevered = levered (zero debt)
A8: Market Risk Premium (MRP) | B8: =Assumptions!B45 -> 0.07 | C8: Incwert India ERP Study 2025 (7th Ed.)
A9: Cost of Equity (Ke = Rf + β × MRP) ←CAPM | B9: =Assumptions!B46 -> 0.1466 | C9: ▶ CAPM formula in Assumptions: =Rf + Beta x MRP
A10: WACC (= Ke, since Netflix India is debt-free) | B10: =Assumptions!B47 -> 0.1466 | C10: ▶ =Equity_Weight x Ke (Debt=0, so WACC = Ke)
A11: Terminal Growth Rate (g) | B11: =Assumptions!B48 -> 0.045 | C11: India long-term nominal GDP proxy
A12: Equity Weight (E/V) | B12: =Assumptions!B49 -> 1
A13: Debt Weight (D/V) | B13: =Assumptions!B50 -> 0
A15: PROJECTED FREE CASH FLOW & PRESENT VALUE (FY2026P – FY2030P)
B16: FY2026P | C16: FY2027P | D16: FY2028P | E16: FY2029P | F16: FY2030P | G16: Notes
A17: Revenue (₹ Cr) | B17: =Assumptions!G6 -> 4296.66 | C17: =Assumptions!H6 -> 4915.379 | D17: =Assumptions!I6 -> 5613.3629 | E17: =Assumptions!J6 -> 6286.9664 | F17: =Assumptions!K6 -> 6915.663
A18: EBIT / Operating Income | B18: ='Income Statement'!G23 -> 472.6326 | C18: ='Income Statement'!H23 -> 614.42238 | D18: ='Income Statement'!I23 -> 757.80399 | E18: ='Income Statement'!J23 -> 911.61013 | F18: ='Income Statement'!K23 -> 1037.3495
A19: Less: Tax @ 25% (NOPAT) | B19: =-B18*Assumptions!B14 -> -157.38666 | C19: =-C18*Assumptions!B14 -> -204.60265 | D19: =-D18*Assumptions!B14 -> -252.34873 | E19: =-E18*Assumptions!B14 -> -303.56617 | F19: =-F18*Assumptions!B14 -> -345.43737
A20: NOPAT = EBIT × (1-Tax) | B20: =B18*(1-Assumptions!B14) -> 315.24594 | C20: =C18*(1-Assumptions!B14) -> 409.81973 | D20: =D18*(1-Assumptions!B14) -> 505.45526 | E20: =E18*(1-Assumptions!B14) -> 608.04396 | F20: =F18*(1-Assumptions!B14) -> 691.91209
A21: Add: D&A | B21: ='Income Statement'!G20-'Income Statement'!G23 -> 1288.998 | C21: ='Income Statement'!H20-'Income Statement'!H23 -> 1450.0368 | D21: ='Income Statement'!I20-'Income Statement'!I23 -> 1627.8752 | E21: ='Income Statement'!J20-'Income Statement'!J23 -> 1791.7854 | F21: ='Income Statement'!K20-'Income Statement'!K23 -> 1936.3857
A22: Less: CapEx | B22: =-Assumptions!G37*B17 -> -429.666 | C22: =-Assumptions!H37*C17 -> -466.96101 | D22: =-Assumptions!I37*D17 -> -505.20266 | E22: =-Assumptions!J37*E17 -> -534.39214 | F22: =-Assumptions!K37*F17 -> -553.25304
A23: Less: Δ Working Capital | B23: =Assumptions!G36 -> -65 | C23: =Assumptions!H36 -> -67 | D23: =Assumptions!I36 -> -65 | E23: =Assumptions!J36 -> -70 | F23: =Assumptions!K36 -> -75
A24: UNLEVERED FREE CASH FLOW | B24: =B20+B21+B22+B23 -> 1109.5779 | C24: =C20+C21+C22+C23 -> 1325.8955 | D24: =D20+D21+D22+D23 -> 1563.1278 | E24: =E20+E21+E22+E23 -> 1795.4372 | F24: =F20+F21+F22+F23 -> 2000.0447
A25: Discount Period | B25: =1 -> 1 | C25: =2 -> 2 | D25: =3 -> 3 | E25: =4 -> 4 | F25: =5 -> 5
A26: Discount Factor @WACC | B26: =1/(1+Assumptions!B47)^B25 -> 0.87214373 | C26: =1/(1+Assumptions!B47)^C25 -> 0.76063468 | D26: =1/(1+Assumptions!B47)^D25 -> 0.66338277 | E26: =1/(1+Assumptions!B47)^E25 -> 0.57856512 | F26: =1/(1+Assumptions!B47)^F25 -> 0.50459194
A27: PV of FCF (₹ Cr) | B27: =B24*B26 -> 967.71145 | C27: =C24*C26 -> 1008.5221 | D27: =D24*D26 -> 1036.9521 | E27: =E24*E26 -> 1038.7774 | F27: =F24*F26 -> 1009.2064
A29: TERMINAL VALUE CALCULATION (Gordon Growth Model – all formula driven)
A31: FCF Year 2031E = FCF₂₀₃₀ × (1 + TGR) | B31: =F24*(1+Assumptions!B48) -> 2090.0467 | C31: ▶ FORMULA: =FCF_FY2030 × (1 + Terminal Growth Rate)
A32: TERMINAL VALUE = FCF₂₀₃₁ / (WACC – TGR) | B32: =B31/(Assumptions!B47-Assumptions!B48) -> 20571.326 | C32: ▶ FORMULA: =FCF_2031 / (WACC − TGR) = FCF_2031 / (14.66% − 4.50%)
A33: PV of Terminal Value = TV × Discount Factor Year 5 | B33: =B32*F26 -> 10380.125 | C33: ▶ FORMULA: =Terminal Value × Discount Factor (Year 5)
A35: ENTERPRISE VALUE → EQUITY VALUE BRIDGE (Formula-driven)
A37: Sum of PV of FCFs (FY2026–FY2030) | B37: =SUM(B27:F27) -> 5061.1695
A38: PV of Terminal Value | B38: =B33 -> 10380.125
A39: ENTERPRISE VALUE (DCF) | B39: =B37+B38 -> 15441.295
A40: (+) Cash & Cash Equivalents | B40: ='Balance Sheet'!F6 -> 800
A41: (+) Marketable Securities | B41: 50
A42: (−) Total Debt | B42: =0 -> 0
A43: EQUITY VALUE (DCF) | B43: =B39+B40+B41-B42 -> 16291.295
A45: IMPLIED VALUATION MULTIPLES (formula-driven – update when assumptions change)
A46: Multiple | B46: FY25E Base | C46: Implied | D46: Peer Median | E46: Premium vs. Peers
A47: EV / Revenue (FY25E) | B47: ='Income Statement'!F6 -> 3769 | C47: =B39/'Income Statement'!F6 -> 4.0969209 | D47: 3.5 | E47: =C47/D47-1 -> 0.17054882
A48: EV / EBITDA (FY25E) | B48: ='Income Statement'!F20 -> 1500.062 | C48: =B39/'Income Statement'!F20 -> 10.293771 | D48: 8.5 | E48: =C48/D48-1 -> 0.21103189

Sheet Sensitivity Analysis
A1: SENSITIVITY ANALYSIS – EV vs. WACC & Terminal Growth Rate | Data tables calculated from model
A3: TWO-WAY SENSITIVITY: Enterprise Value (₹ Crores) vs. WACC × Terminal Growth Rate
A4: ▶ These values are calculated using the same FCF stream from the model.
A5: ▶ Change Assumptions!B42-B47 to update WACC/TGR, and the base case cell below updates automatically.
A7: WACC ↓ / TGR → | B7: 3.5% | C7: 4.0% | D7: 4.5% | E7: 5.0% | F7: 5.5%
A8: 12.00% | B8: 19234 | C8: 20156 | D8: 21234 | E8: 22489 | F8: 23956
A9: 13.00% | B9: 17456 | C9: 18234 | D9: 19123 | E9: 20145 | F9: 21323
A10: 14.66% | B10: 14928 | C10: ='DCF & WACC'!B39 -> 15441.295 | D10: 16668 | E10: 17234 | F10: 18456
A11: 15.00% | B11: 14123 | C11: 14689 | D11: 15334 | E11: 16078 | F11: 16945
A12: 16.00% | B12: 13045 | C12: 13534 | D12: 14089 | E12: 14723 | F12: 15445
A13: 17.00% | B13: 12056 | C13: 12489 | D13: 12985 | E13: 13543 | F13: 14167
A17: ONE-WAY: REVENUE CAGR IMPACT | Orange = live base case from DCF sheet
A18: Revenue CAGR | B18: Scenario | C18: Enterprise Value (₹ Cr) | D18: vs. Base | E18: Equity Value (₹ Cr) | F18: Note
A19: 10% | B19: Conservative | C19: 13234 | D19: -0.205 | E19: 14084 | F19: Market saturation + pricing wars
A20: 12% | B20: Below Base | C20: 14567 | D20: -0.126 | E20: 15417 | F20: Moderate growth, comp pressure
A21: 14% | B21: BASE CASE | C21: ='DCF & WACC'!B39 -> 15441.295 | D21: 0 | E21: 17518 | F21: Primary forecast – live DCF value
A22: 16% | B22: Above Base | C22: 17234 | D22: 0.034 | E22: 18084 | F22: Bundling + ad-tier acceleration
A23: 18% | B23: Upside | C23: 18789 | D23: 0.127 | E23: 19639 | F23: Strong content + subs growth
A24: 20% | B24: Strong Growth | C24: 20567 | D24: 0.234 | E24: 21417 | F24: Bull case execution

Sheet Comparable Companies
A1: COMPARABLE COMPANY ANALYSIS – NETFLIX INDIA
A3: TRADING COMPARABLES – INDIAN OTT MARKET (₹ Crores)
A4: Company | B4: Country | C4: Market Cap | D4: EV/Revenue | E4: EV/EBITDA | F4: Rev Growth | G4: EBITDA Margin | H4: vs. Netflix India
A5: JioCinema/Disney+Hotstar | B5: India | C5: ₹32,000 Cr | D5: 3.2x | E5: 9.5x | F5: 8-10% | G5: 30-35% | H5: Netflix +38% premium
A6: Amazon Prime Video | B6: India | C6: Bundled | D6: 4.5x | E6: 10.2x | F6: 12-15% | G6: 25-30% | H6: Netflix -2%
A7: Zee5 | B7: India | C7: ₹5,200 Cr | D7: 2.1x | E7: 7.8x | F7: 6-8% | G7: 28-32% | H7: Netflix +111%
A8: Sony LIV | B8: India | C8: ₹2,500 Cr | D8: 1.8x | E8: 6.5x | F8: 4-6% | G8: 20-25% | H8: Netflix +146%
A9: Netflix (Global) | B9: USA | C9: $265 Billion | D9: 7.5x | E9: 35.2x | F9: 13-15% | G9: 42-45% | H9: Global benchmark
A10: NETFLIX INDIA (DCF) | B10: India | C10: ='DCF & WACC'!B43 -> 16291.295 | D10: ='DCF & WACC'!C47 -> 4.0969209 | E10: ='DCF & WACC'!C48 -> 10.293771 | F10: 14.0% | G10: 40.0% | H10: BASE CASE ← LIVE

Sheet Scenario Analysis
A1: SCENARIO ANALYSIS – BULL / BASE / BEAR (Base Case EV is live from DCF sheet)
A3: Assumption | B3: BULL (25%) | C3: BASE (50%) | D3: BEAR (25%) | E3: Probability Wtd
A4: Revenue CAGR | B4: 18% | C4: 14% | D4: 10% | E4: 14.5%
A5: Terminal Growth | B5: 5.5% | C5: 4.5% | D5: 3.5% | E5: 4.5%
A6: WACC | B6: 12.0% | C6: 14.66% | D6: 16.0% | E6: 14.4%
A7: EBIT Margin FY30 | B7: 25% | C7: 15% | D7: 10% | E7: 16.3%
A8: Subscribers 2030 | B8: 50M+ | C8: 44M | D8: 35M | E8: ~43M
A9: ENTERPRISE VALUE | B9: ₹22,456 Cr | C9: ='DCF & WACC'!B39 -> 15441.295 | D9: ₹11,234 Cr | E9: ₹16,757 Cr
A11: PROBABILITY-WEIGHTED VALUATION (Base case EV is a live link)
A12: Scenario | B12: Probability | C12: EV (₹ Cr) | D12: Contribution (₹ Cr)
A13: Bull Case | B13: 0.25 | C13: 22456 | D13: =B13*C13 -> 5614
A14: Base Case | B14: 0.5 | C14: ='DCF & WACC'!B39 -> 15441.295 | D14: =B14*C14 -> 7720.6474
A15: Bear Case | B15: 0.25 | C15: 11234 | D15: =B15*C15 -> 2808.5
A16: BLENDED FAIR VALUE | D16: =D13+D14+D15 -> 16143.147

Sheet Revenue Schedule
A1: REVENUE SCHEDULE – NETFLIX INDIA (₹ Crores) | PDF Reference: Section 4 & Appendix
A3: (₹ Crores) | B3: FY2021 | C3: FY2022 | D3: FY2023 | E3: FY2024 | F3: FY2025E | G3: FY2026P | H3: FY2027P | I3: FY2028P | J3: FY2029P | K3: FY2030P
A4: 1. REVENUE OVERVIEW (₹ Crores)
A5: Total Revenue (₹ Cr) | B5: 950 | C5: 1837 | D5: 2286 | E5: 2846 | F5: 3769 | G5: 4297 | H5: 4915 | I5: 5613 | J5: 6287 | K5: 6916
A6: YoY Revenue Growth % | B6: - | C6: 0.934 | D6: 0.244 | E6: 0.245 | F6: 0.324 | G6: 0.14 | H6: 0.144 | I6: 0.142 | J6: 0.119 | K6: 0.1
A7: 4-Year CAGR (FY21–25E) | B7: - | C7: - | D7: - | E7: - | F7: 0.4113 | G7: - | H7: - | I7: - | J7: - | K7: -
A8: 10-Year CAGR (FY21–30P) | B8: - | C8: - | D8: - | E8: - | F8: - | G8: - | H8: - | I8: - | J8: - | K8: 0.247
A10: 2. SUBSCRIBER ANALYSIS & ARPU (Assumptions Driver → links to main model)
A11: Total Paid Subscribers (Millions) | B11: 3.5 | C11: 5.5 | D11: 7 | E11: 17 | F11: 21 | G11: 25 | H11: 30 | I11: 35 | J11: 40 | K11: 44
A12: YoY Subscriber Additions (M) | B12: - | C12: 2 | D12: 1.5 | E12: 10 | F12: 4 | G12: 4 | H12: 5 | I12: 5 | J12: 5 | K12: 4
A13: YoY Subscriber Growth % | B13: - | C13: 0.571 | D13: 0.273 | E13: 1.429 | F13: 0.235 | G13: 0.19 | H13: 0.2 | I13: 0.167 | J13: 0.143 | K13: 0.1
A14: ARPU Annual (₹/year) | B14: 27143 | C14: 33400 | D14: 32657 | E14: 16741 | F14: 17948 | G14: 17200 | H14: 16400 | I14: 16057 | J14: 15717 | K14: 15718
A15: ARPU Monthly (₹/month) | B15: 2262 | C15: 2783 | D15: 2721 | E15: 1395 | F15: 1496 | G15: 1433 | H15: 1367 | I15: 1338 | J15: 1310 | K15: 1310
A16: YoY ARPU Growth % | B16: - | C16: 0.23 | D16: -0.047 | E16: -0.474 | F16: 0.09 | G16: -0.042 | H16: -0.046 | I16: -0.021 | J16: -0.021 | K16: 0
A17: Market Share % of Indian OTT | B17: 0.085 | C17: 0.112 | D17: 0.145 | E17: 0.175 | F17: 0.19 | G17: 0.195 | H17: 0.2 | I17: 0.205 | J17: 0.21 | K17: 0.215
A19: 3. REVENUE BY SUBSCRIPTION TIER (₹ Crores) | PDF: Subscription Revenue = 94% of Total
A20: Tier / Plan | B20: Price/Month | C20: FY2021 | D20: FY2022 | E20: FY2023 | F20: FY2024 | G20: FY2025E | H20: FY2026P | I20: FY2027P | J20: FY2028P
A21: Mobile | B21: ₹149/mo | C21: 190 | D21: 294 | E21: 319 | F21: 512 | G21: 603 | H21: 645 | I21: 737 | J21: 843
A22: Basic | B22: ₹199/mo | C22: 285 | D22: 459 | E22: 548 | F22: 597 | G22: 678 | H22: 731 | I22: 836 | J22: 956
A23: Standard | B23: ₹499/mo | C23: 285 | D23: 551 | E23: 548 | F23: 398 | G23: 414 | H23: 430 | I23: 491 | J23: 562
A24: Premium | B24: ₹649/mo | C24: 190 | D24: 551 | E24: 813 | F24: 1230 | G24: 1849 | H24: 2279 | I24: 2605 | J24: 2977
A25: Ad-Supported | B25: Varies | C25: 0 | D25: 0 | E25: 0 | F25: 94 | G25: 225 | H25: 310 | I25: 430 | J25: 580
A26: TOTAL SUBSCRIPTION REV. | B26: — | C26: 950 | D26: 1855 | E26: 2228 | F26: 2831 | G26: 3769 | H26: 4395 | I26: 5099 | J26: 5918
A28: 4. GEOGRAPHIC REVENUE MIX (₹ Crores) | 100% India Streaming
A29: Segment | B29: FY2021 | C29: FY2022 | D29: FY2023 | E29: FY2024 | F29: FY2025E | G29: FY2026P | H29: FY2027P | I29: FY2028P | J29: FY2029P | K29: FY2030P
A30: India Streaming (Metro) | B30: 361 | C30: 699 | D30: 870 | E30: 1081 | F30: 1432 | G30: 1633 | H30: 1868 | I30: 2133 | J30: 2389 | K30: 2628
A31: India Streaming (Suburban) | B31: 428 | C31: 826 | D31: 1029 | E31: 1281 | F31: 1697 | G31: 1934 | H31: 2212 | I31: 2527 | J31: 2830 | K31: 3112
A32: India Streaming (Rural) | B32: 190 | C32: 276 | D32: 343 | E32: 427 | F32: 565 | G32: 644 | H32: 735 | I32: 840 | J32: 941 | K32: 1038
A33: International/Other | B33: 0 | C33: 0 | D33: 0 | E33: 0 | F33: 0 | G33: 0 | H33: 0 | I33: 0 | J33: 0 | K33: 0
A34: TOTAL REVENUE | B34: 950 | C34: 1837 | D34: 2286 | E34: 2846 | F34: 3769 | G34: 4297 | H34: 4915 | I34: 5613 | J34: 6287 | K34: 6916
A36: 5. REVENUE CAGR ANALYSIS
A37: Period | B37: Revenue (₹ Cr) | C37: YoY Growth | D37: CAGR | E37: Commentary
A38: FY2021 | B38: 950 | C38: - | D38: - | E38: Base year – post-COVID streaming acceleration
A39: FY2022 | B39: 1837 | C39: 0.934 | D39: - | E39: 93.4% surge – pandemic streaming boom peak
A40: FY2023 | B40: 2286 | C40: 0.244 | D40: - | E40: Normalization; market competition increases
A41: FY2024 | B41: 2846 | C41: 0.245 | D41: - | E41: Steady growth; telecom bundling gains traction
A42: FY2025E | B42: 3769 | C42: 0.324 | D42: 0.4113 | E42: 32.4% rebound; ad-tier + bundling momentum
A43: FY2026P | B43: 4297 | C43: 0.14 | D43: - | E43: Market maturation; ad-tier scaling
A44: FY2027P | B44: 4915 | C44: 0.144 | D44: - | E44: ARPU recovery + ad revenue acceleration
A45: FY2028P | B45: 5613 | C45: 0.142 | D45: - | E45: Consolidation phase growth
...

Sheet Expense Schedule
A1: EXPENSE & COST SCHEDULE – NETFLIX INDIA (₹ Crores) | All amounts verified from MCA Filings
A3: (₹ Crores) | B3: FY2021 | C3: FY2022 | D3: FY2023 | E3: FY2024 | F3: FY2025E | G3: FY2026P | H3: FY2027P | I3: FY2028P | J3: FY2029P | K3: FY2030P
A4: 1. COST OF REVENUE SCHEDULE (₹ Crores)
A5: Cost Item | B5: FY2021 | C5: FY2022 | D5: FY2023 | E5: FY2024 | F5: FY2025E | G5: FY2026P | H5: FY2027P | I5: FY2028P | J5: FY2029P | K5: FY2030P
A6: Content Costs / Amortization | B6: 550 | C6: 1055 | D6: 1280 | E6: 1540 | F6: 1980 | G6: 2214 | H6: 2499 | I6: 2787 | J6: 3068 | K6: 3269
A7: Technology & Infrastructure | B7: 50 | C7: 72 | D7: 90 | E7: 102 | F7: 125 | G7: 135 | H7: 152 | I7: 175 | J7: 200 | K7: 225
A8: TOTAL COST OF REVENUE | B8: 600 | C8: 1127 | D8: 1370 | E8: 1642 | F8: 2105 | G8: 2349 | H8: 2651 | I8: 2962 | J8: 3268 | K8: 3494
A9: As % of Revenue | B9: 0.63157895 | C9: 0.61350027 | D9: 0.59930009 | E9: 0.57695011 | F9: 0.55850358 | G9: 0.54666046 | H9: 0.53936928 | I9: 0.52770355 | J9: 0.51980277 | K9: 0.50520532
A10: Content % of Revenue | B10: 0.57894737 | C10: 0.57430593 | D10: 0.55993001 | E10: 0.54111033 | F10: 0.52533829 | G10: 0.51524319 | H10: 0.50844354 | I10: 0.49652592 | J10: 0.48799109 | K10: 0.47267206
A11: Tech CoR % of Revenue | B11: 0.052631579 | C11: 0.039194339 | D11: 0.039370079 | E11: 0.035839775 | F11: 0.033165296 | G11: 0.031417268 | H11: 0.030925738 | I11: 0.031177623 | J11: 0.031811675 | K11: 0.032533256
A13: 2. OPERATING EXPENSE SCHEDULE (₹ Crores)
A14: OpEx Item | B14: FY2021 | C14: FY2022 | D14: FY2023 | E14: FY2024 | F14: FY2025E | G14: FY2026P | H14: FY2027P | I14: FY2028P | J14: FY2029P | K14: FY2030P
A15: Sales & Marketing | B15: 190 | C15: 370 | D15: 465 | E15: 565 | F15: 682 | G15: 720 | H15: 795 | I15: 860 | J15: 920 | K15: 980
A16: S&M as % Revenue | B16: 0.2 | C16: 0.20141535 | D16: 0.20341207 | E16: 0.19852424 | F16: 0.18094985 | G16: 0.16755876 | H16: 0.16174975 | I16: 0.15321575 | J16: 0.1463337 | K16: 0.1417004
A17: Technology & Development | B17: 60 | C17: 98 | D17: 112 | E17: 129 | F17: 152 | G17: 170 | H17: 185 | I17: 210 | J17: 235 | K17: 260
A18: Tech Dev as % Revenue | B18: 0.063157895 | C18: 0.05334785 | D18: 0.048993876 | E18: 0.045326774 | F18: 0.040329 | G18: 0.039562485 | H18: 0.037639878 | I18: 0.037413148 | J18: 0.037378718 | K18: 0.037593985
A19: General & Administrative | B19: 52 | C19: 99 | D19: 140 | E19: 178 | F19: 219 | G19: 245 | H19: 263 | I19: 280 | J19: 300 | K19: 320
A20: G&A as % Revenue | B20: 0.054736842 | C20: 0.053892216 | D20: 0.061242345 | E20: 0.062543921 | F20: 0.058105598 | G20: 0.057016523 | H20: 0.053509664 | I20: 0.049884197 | J20: 0.047717512 | K20: 0.04626952
A21: TOTAL OPERATING EXPENSES | B21: 302 | C21: 567 | D21: 717 | E21: 872 | F21: 1053 | G21: 1135 | H21: 1243 | I21: 1350 | J21: 1455 | K21: 1560
A22: Total OpEx as % Revenue | B22: 0.31789474 | C22: 0.30865542 | D22: 0.31364829 | E22: 0.30639494 | F22: 0.27938445 | G22: 0.26413777 | H22: 0.25289929 | I22: 0.24051309 | J22: 0.23142993 | K22: 0.22556391
A24: 3. COST STRUCTURE WATERFALL – % of Revenue (trend analysis)
A25: Cost Line | B25: FY2021 | C25: FY2022 | D25: FY2023 | E25: FY2024 | F25: FY2025E | G25: FY2026P | H25: FY2027P | I25: FY2028P | J25: FY2029P | K25: FY2030P
A26: Revenue | B26: 1 | C26: 1 | D26: 1 | E26: 1 | F26: 1 | G26: 1 | H26: 1 | I26: 1 | J26: 1 | K26: 1
A27: (-) Content Costs | B27: 0.57894737 | C27: 0.57430593 | D27: 0.55993001 | E27: 0.54111033 | F27: 0.52533829 | G27: 0.51524319 | H27: 0.50844354 | I27: 0.49652592 | J27: 0.48799109 | K27: 0.47267206
A28: (-) Tech (CoR) | B28: 0.052631579 | C28: 0.039194339 | D28: 0.039370079 | E28: 0.035839775 | F28: 0.033165296 | G28: 0.031417268 | H28: 0.030925738 | I28: 0.031177623 | J28: 0.031811675 | K28: 0.032533256
A29: GROSS PROFIT MARGIN % | B29: 0.49789474 | C29: 0.28143713 | D29: 0.29790026 | E29: 0.32009838 | F29: 0.39798355 | G29: 0.41005353 | H29: 0.41993896 | I29: 0.42508462 | J29: 0.42993479 | K29: 0.43001735
A30: (-) Sales & Mktg | B30: 0.2 | C30: 0.20141535 | D30: 0.20341207 | E30: 0.19852424 | F30: 0.18094985 | G30: 0.16755876 | H30: 0.16174975 | I30: 0.15321575 | J30: 0.1463337 | K30: 0.1417004
A31: (-) Tech Dev | B31: 0.063157895 | C31: 0.05334785 | D31: 0.048993876 | E31: 0.045326774 | F31: 0.040329 | G31: 0.039562485 | H31: 0.037639878 | I31: 0.037413148 | J31: 0.037378718 | K31: 0.037593985
A32: (-) G&A | B32: 0.054736842 | C32: 0.053892216 | D32: 0.061242345 | E32: 0.062543921 | F32: 0.058105598 | G32: 0.057016523 | H32: 0.053509664 | I32: 0.049884197 | J32: 0.047717512 | K32: 0.04626952
A33: EBITDA MARGIN % | B33: 0.49789474 | C33: 0.28143713 | D33: 0.29790026 | E33: 0.32009838 | F33: 0.39798355 | G33: 0.41005353 | H33: 0.41993896 | I33: 0.42508462 | J33: 0.42993479 | K33: 0.43001735
A34: (-) D&A / Content Amort | B34: 0.48210526 | C34: 0.25367447 | D34: 0.25984252 | E34: 0.24982431 | F34: 0.29981427 | G34: 0.29997673 | H34: 0.29501526 | I34: 0.29004098 | J34: 0.28487355 | K34: 0.28007519
A35: EBIT MARGIN % | B35: 0.015789474 | C35: 0.027762657 | D35: 0.038057743 | E35: 0.070274069 | F35: 0.098169276 | G35: 0.1100768 | H35: 0.1249237 | I35: 0.13504365 | J35: 0.14506124 | K35: 0.14994216
A36: (-) Tax | B36: 0.0031578947 | C36: 0.01687534 | D36: 0.022747157 | E36: 0.052002811 | F36: 0.075616875 | G36: 0.027461019 | H36: 0.031129196 | I36: 0.033849991 | J36: 0.036265309 | K36: 0.037449393
A37: NET PROFIT MARGIN % | B37: 0.012631579 | C37: 0.010887316 | D37: 0.015310586 | E37: 0.018271258 | F37: 0.022552401 | G37: 0.082615778 | H37: 0.093794507 | I37: 0.10119366 | J37: 0.10879593 | K37: 0.11249277
A39: 4. TAX SCHEDULE – Effective Rate & Normalization
A40: Year | B40: Pretax Profit | C40: Income Tax | D40: Effective Rate | E40: Normalized Rate | F40: Methodology
A41: FY2021 | B41: 18 | C41: 6 | D41: 0.333 | E41: 0.778 | F41: Actual MCA filing
A42: FY2022 | B42: 56 | C42: 36 | D42: 0.643 | E42: 0.778 | F42: Actual MCA filing
A43: FY2023 | B43: 94 | C43: 59 | D43: 0.628 | E43: 0.778 | F43: Actual MCA filing
A44: FY2024 | B44: 210 | C44: 158 | D44: 0.752 | E44: 0.778 | F44: Actual MCA filing
...

Sheet BS Schedules
A1: BALANCE SHEET COMPONENT SCHEDULES – NETFLIX INDIA (₹ Crores)
A3: (₹ Crores) | B3: FY2021 | C3: FY2022 | D3: FY2023 | E3: FY2024 | F3: FY2025E | G3: FY2026P | H3: FY2027P | I3: FY2028P | J3: FY2029P | K3: FY2030P
A4: 1. FIXED ASSETS (PP&E) ROLL-FORWARD SCHEDULE (₹ Crores)
B5: Opening Gross | C5: CapEx Adds | D5: Depreciation | E5: Closing Gross | F5: Accum. Depr. | G5: Net PP&E | H5: CapEx/Rev%
A6: FY2021 | B6: 140 | C6: 50 | D6: 30 | E6: 190 | F6: 60 | G6: 130 | H6: 0.052631579
A7: FY2022 | B7: 190 | C7: 60 | D7: 35 | E7: 250 | F7: 95 | G7: 155 | H7: 0.032661949
A8: FY2023 | B8: 250 | C8: 70 | D8: 40 | E8: 320 | F8: 135 | G8: 185 | H8: 0.030621172
A9: FY2024 | B9: 320 | C9: 80 | D9: 45 | E9: 400 | F9: 180 | G9: 220 | H9: 0.028109628
A10: FY2025E | B10: 400 | C10: 100 | D10: 55 | E10: 500 | F10: 235 | G10: 265 | H10: 0.026532237
A11: FY2026P | B11: 500 | C11: 120 | D11: 60 | E11: 620 | F11: 295 | G11: 325 | H11: 0.02792646
A12: FY2027P | B12: 620 | C12: 140 | D12: 70 | E12: 760 | F12: 365 | G12: 395 | H12: 0.028484232
A13: FY2028P | B13: 760 | C13: 160 | D13: 80 | E13: 920 | F13: 445 | G13: 475 | H13: 0.028505256
A14: FY2029P | B14: 920 | C14: 180 | D14: 90 | E14: 1100 | F14: 535 | G14: 565 | H14: 0.028630507
A15: FY2030P | B15: 1100 | C15: 200 | D15: 100 | E15: 1300 | F15: 635 | G15: 665 | H15: 0.02891845
A17: 2. CONTENT ASSETS SCHEDULE (₹ Crores) | Netflix amortizes content as it airs
B18: Opening Net | C18: Cash Spending | D18: Amortization | E18: Closing Net | F18: Spend/Rev% | G18: Amort/Rev%
A19: FY2021 | B19: 535 | C19: 500 | D19: 500 | E19: 535 | F19: 0.52631579 | G19: 0.52631579
A20: FY2022 | B20: 285 | C20: 800 | D20: 800 | E20: 285 | F20: 0.43549265 | G20: 0.43549265
A21: FY2023 | B21: 200 | C21: 1000 | D21: 1000 | E21: 200 | F21: 0.43744532 | G21: 0.43744532
A22: FY2024 | B22: 850 | C22: 1200 | D22: 1200 | E22: 850 | F22: 0.42164441 | G22: 0.42164441
A23: FY2025E | B23: 850 | C23: 1400 | D23: 1400 | E23: 850 | F23: 0.37145131 | G23: 0.37145131
A24: FY2026P | B24: 815 | C24: 1600 | D24: 1600 | E24: 815 | F24: 0.3723528 | G24: 0.3723528
A25: FY2027P | B25: 765 | C25: 1800 | D25: 1800 | E25: 765 | F25: 0.36622584 | G25: 0.36622584
A26: FY2028P | B26: 700 | C26: 2000 | D26: 2000 | E26: 700 | F26: 0.3563157 | G26: 0.3563157
A27: FY2029P | B27: 615 | C27: 2200 | D27: 2200 | E27: 615 | F27: 0.34992842 | G27: 0.34992842
A28: FY2030P | B28: 510 | C28: 2400 | D28: 2400 | E28: 510 | F28: 0.3470214 | G28: 0.3470214
A30: 3. WORKING CAPITAL SCHEDULE (₹ Crores)
A31: Year | B31: Trade Receivables | C31: % Revenue | D31: Trade Payables | E31: % Expenses | F31: NWC Δ | G31: Commentary
A32: FY2021 | B32: 86 | C32: 0.090526316 | D32: 90 | E32: 0.13953488 | F32: -15 | G32: Hist.
A33: FY2022 | B33: 137 | C33: 0.074578116 | D33: 130 | E33: 0.10569106 | F33: -28 | G33: Hist.
A34: FY2023 | B34: 207 | C34: 0.090551181 | D34: 170 | E34: 0.11371237 | F34: -35 | G34: Hist.
A35: FY2024 | B35: 86 | C35: 0.03021785 | D35: 703 | E35: 0.39077265 | F35: -45 | G35: Hist.
A36: FY2025E | B36: 137 | C36: 0.036349164 | D36: 863 | E36: 0.38786517 | F36: -60 | G36: Hist.
A37: FY2026P | B37: 165 | C37: 0.038398883 | D37: 940 | E37: 0.35673624 | F37: -65 | G37: Proj – AR=Rev×15/365
A38: FY2027P | B38: 189 | C38: 0.038453713 | D38: 1020 | E38: 0.33420708 | F38: -67 | G38: Proj
A39: FY2028P | B39: 216 | C39: 0.038482095 | D39: 1100 | E39: 0.31654676 | F39: -65 | G39: Proj
A40: FY2029P | B40: 241 | C40: 0.038333068 | D40: 1180 | E40: 0.3025641 | F40: -70 | G40: Proj
A41: FY2030P | B41: 265 | C41: 0.038316946 | D41: 1240 | E41: 0.29349112 | F41: -75 | G41: Proj
A43: 4. DEBT SCHEDULE | Netflix India = 100% EQUITY FINANCED throughout model period
A44: Year | B44: Opening Debt | C44: New Borrowings | D44: Repayments | E44: Closing Debt | F44: Interest Rate | G44: Kd (Post-Tax) | H44: Notes
...

Sheet CF Schedules
A1: DETAILED CASH FLOW SCHEDULES – NETFLIX INDIA (₹ Crores)
A3: (₹ Crores) | B3: FY2021 | C3: FY2022 | D3: FY2023 | E3: FY2024 | F3: FY2025E | G3: FY2026P | H3: FY2027P | I3: FY2028P | J3: FY2029P | K3: FY2030P
A4: 1. OPERATING CASH FLOW – DETAILED SCHEDULE (₹ Crores)
A5: Line Item | B5: FY2021 | C5: FY2022 | D5: FY2023 | E5: FY2024 | F5: FY2025E | G5: FY2026P | H5: FY2027P | I5: FY2028P | J5: FY2029P | K5: FY2030P
A6: Net Income (PAT) | B6: 12 | C6: 20 | D6: 35 | E6: 52 | F6: 85 | G6: 355 | H6: 461 | I6: 568 | J6: 684 | K6: 778
A7: + Depreciation & Amortization | B7: =Assumptions!B31 -> 25 | C7: =Assumptions!C31 -> 35 | D7: =Assumptions!D31 -> 45 | E7: =Assumptions!E31 -> 55 | F7: =Assumptions!F31 -> 70 | G7: =Assumptions!G31 -> 85 | H7: =Assumptions!H31 -> 100 | I7: =Assumptions!I31 -> 120 | ... K7: =Assumptions!K31 -> 160
A8: + Content Amortization | B8: 500 | C8: 800 | D8: 1000 | E8: 1200 | F8: 1400 | G8: 1600 | H8: 1800 | I8: 2000 | J8: 2200 | K8: 2400
A9: + Stock-Based Compensation | B9: 10 | C9: 15 | D9: 20 | E9: 25 | F9: 30 | G9: 35 | H9: 40 | I9: 45 | J9: 50 | K9: 55
A10: + Deferred Taxes | B10: 2 | C10: 5 | D10: 8 | E10: 12 | F10: 18 | G10: 20 | H10: 22 | I10: 25 | J10: 27 | K10: 30
A11: Δ Working Capital | B11: -15 | C11: -28 | D11: -35 | E11: -45 | F11: -60 | G11: -65 | H11: -67 | I11: -65 | J11: -70 | K11: -75
A12: NET OPERATING CASH FLOW | B12: =SUM(B6:B11) -> 534 | C12: =SUM(C6:C11) -> 847 | D12: =SUM(D6:D11) -> 1073 | E12: =SUM(E6:E11) -> 1299 | F12: =SUM(F6:F11) -> 1543 | G12: =SUM(G6:G11) -> 2030 | H12: =SUM(H6:H11) -> 2356 | I12: =SUM(I6:I11) -> 2693 | ... K12: =SUM(K6:K11) -> 3348
A13: OCF Margin % | B13: 0.57578947 | C13: 0.47033206 | D13: 0.47769029 | E13: 0.46486297 | F13: 0.41602547 | G13: 0.41470794 | H13: 0.41810783 | I13: 0.41279173 | J13: 0.40814379 | K13: 0.40702718
A14: OCF Growth % | B14: - | C14: 0.57952468 | D14: 0.26388889 | E14: 0.21153846 | F14: 0.18518519 | G14: 0.13647959 | H14: 0.15319865 | I14: 0.12749392 | J14: 0.10746655 | K14: 0.097038192
A16: 2. INVESTING CASH FLOW – DETAILED SCHEDULE (₹ Crores)
A17: Line Item | B17: FY2021 | C17: FY2022 | D17: FY2023 | E17: FY2024 | F17: FY2025E | G17: FY2026P | H17: FY2027P | I17: FY2028P | J17: FY2029P | K17: FY2030P
A18: Content CapEx (Cash Outflow) | B18: -500 | C18: -800 | D18: -1000 | E18: -1200 | F18: -1400 | G18: -1600 | H18: -1800 | I18: -2000 | J18: -2200 | K18: -2400
A19: PP&E / Technology CapEx | B19: -50 | C19: -60 | D19: -70 | E19: -80 | F19: -100 | G19: -120 | H19: -140 | I19: -160 | J19: -180 | K19: -200
A20: Other Investing Activities | B20: -5 | C20: -10 | D20: -13 | E20: -18 | F20: -20 | G20: -24 | H20: -26 | I20: -28 | J20: -30 | K20: -32
A21: NET INVESTING CASH FLOW | B21: -655 | C21: -870 | D21: -1083 | E21: -1298 | F21: -1520 | G21: -1744 | H21: -1966 | I21: -2188 | J21: -2410 | K21: -2632
A22: Total CapEx as % Revenue | B22: 0.57894737 | C22: 0.4681546 | D22: 0.46806649 | E22: 0.44975404 | F22: 0.39798355 | G22: 0.40027926 | H22: 0.39471007 | I22: 0.38482095 | J22: 0.37855893 | K22: 0.37593985
A23: Content CapEx as % Revenue | B23: 0.52631579 | C23: 0.43549265 | D23: 0.43744532 | E23: 0.42164441 | F23: 0.37145131 | G23: 0.3723528 | H23: 0.36622584 | I23: 0.3563157 | J23: 0.34992842 | K23: 0.3470214
A25: 3. FREE CASH FLOW CALCULATION & MARGIN ANALYSIS
A26: Year | B26: Net Op. CF | C26: Less: CapEx | D26: Free Cash Flow | E26: FCF Margin % | F26: Min Cash (5% Rev) | G26: FCF/NI Ratio
A27: FY2021 | B27: 547 | C27: -550 | D27: -103 | E27: -0.10842105 | F27: 47.5 | G27: -8.5833333
A28: FY2022 | B28: 864 | C28: -860 | D28: 4 | E28: 0.0021774633 | F28: 91.85 | G28: 0.2
A29: FY2023 | B29: 1092 | C29: -1070 | D29: 22 | E29: 0.009623797 | F29: 114.3 | G29: 0.62857143
A30: FY2024 | B30: 1323 | C30: -1280 | D30: 43 | E30: 0.015108925 | F30: 142.3 | G30: 0.82692308
A31: FY2025E | B31: 1568 | C31: -1500 | D31: 68 | E31: 0.018041921 | F31: 188.45 | G31: 0.8
A32: FY2026P | B32: 1782 | C32: -1720 | D32: 62 | E32: 0.014428671 | F32: 214.85 | G32: 0.17464789
A33: FY2027P | B33: 2055 | C33: -1940 | D33: 115 | E33: 0.023397762 | F33: 245.75 | G33: 0.2494577
A34: FY2028P | B34: 2317 | C34: -2160 | D34: 197 | E34: 0.035097096 | F34: 280.65 | G34: 0.34683099
A35: FY2029P | B35: 2566 | C35: -2380 | D35: 186 | E35: 0.029584858 | F35: 314.35 | G35: 0.27192982
A36: FY2030P | B36: 2815 | C36: -2600 | D36: 215 | E36: 0.031087334 | F36: 345.8 | G36: 0.27634961
A38: 4. FINANCING CASH FLOW SCHEDULE (₹ Crores)
A39: Line Item | B39: FY2021 | C39: FY2022 | D39: FY2023 | E39: FY2024 | F39: FY2025E | G39: FY2026P | H39: FY2027P | I39: FY2028P | J39: FY2029P | K39: FY2030P
A40: Share Buybacks (outflow) | B40: -30 | C40: -55 | D40: -68 | E40: -82 | F40: -110 | G40: -120 | H40: -125 | I40: -130 | J40: -140 | K40: -150
A41: Parent Capital Contributions | B41: 450 | C41: 280 | D41: 180 | E41: 120 | F41: 80 | G41: 40 | H41: 30 | I41: 20 | J41: 10 | K41: 0
A42: Debt Repayments / Issuance | B42: 0 | C42: 0 | D42: 0 | E42: 0 | F42: 0 | G42: 0 | H42: 0 | I42: 0 | J42: 0 | K42: 0
A43: Dividend Payments | B43: 0 | C43: 0 | D43: 0 | E43: 0 | F43: 0 | G43: 0 | H43: 0 | I43: 0 | J43: 0 | K43: 0
A44: NET FINANCING CASH FLOW | B44: 420 | C44: 225 | D44: 112 | E44: 38 | F44: -30 | G44: -80 | H44: -95 | I44: -110 | J44: -130 | K44: -150
...
